telegram.ext.updater - WARNING - Exiting immediately!
telegram.ext.updater - WARNING - Exiting immediately!
telegram.ext.updater - ERROR - Error while getting Updates: Timed out
telegram.ext.dispatcher - ERROR - No error handlers are registered, logging exception...
Traceback (most recent call last):
  File "/Users/miklash90/projects/lessons1/env/lib/python3.5/site-packages/telegram/vendor/ptb_urllib3/urllib3/connectionpool.py", line 402, in _make_request
    six.raise_from(e, None)
  File "<string>", line 2, in raise_from
  File "/Users/miklash90/projects/lessons1/env/lib/python3.5/site-packages/telegram/vendor/ptb_urllib3/urllib3/connectionpool.py", line 398, in _make_request
    httplib_response = conn.getresponse()
  File "/Library/Frameworks/Python.framework/Versions/3.5/lib/python3.5/http/client.py", line 1198, in getresponse
    response.begin()
  File "/Library/Frameworks/Python.framework/Versions/3.5/lib/python3.5/http/client.py", line 297, in begin
    version, status, reason = self._read_status()
  File "/Library/Frameworks/Python.framework/Versions/3.5/lib/python3.5/http/client.py", line 258, in _read_status
    line = str(self.fp.readline(_MAXLINE + 1), "iso-8859-1")
  File "/Library/Frameworks/Python.framework/Versions/3.5/lib/python3.5/socket.py", line 576, in readinto
    return self._sock.recv_into(b)
  File "/Library/Frameworks/Python.framework/Versions/3.5/lib/python3.5/ssl.py", line 937, in recv_into
    return self.read(nbytes, buffer)
  File "/Library/Frameworks/Python.framework/Versions/3.5/lib/python3.5/ssl.py", line 799, in read
    return self._sslobj.read(len, buffer)
  File "/Library/Frameworks/Python.framework/Versions/3.5/lib/python3.5/ssl.py", line 583, in read
    v = self._sslobj.read(len, buffer)
socket.timeout: The read operation timed out

During handling of the above exception, another exception occurred:

Traceback (most recent call last):
  File "/Users/miklash90/projects/lessons1/env/lib/python3.5/site-packages/telegram/utils/request.py", line 190, in _request_wrapper
    resp = self._con_pool.request(*args, **kwargs)
  File "/Users/miklash90/projects/lessons1/env/lib/python3.5/site-packages/telegram/vendor/ptb_urllib3/urllib3/request.py", line 70, in request
    **urlopen_kw)
  File "/Users/miklash90/projects/lessons1/env/lib/python3.5/site-packages/telegram/vendor/ptb_urllib3/urllib3/request.py", line 148, in request_encode_body
    return self.urlopen(method, url, **extra_kw)
  File "/Users/miklash90/projects/lessons1/env/lib/python3.5/site-packages/telegram/vendor/ptb_urllib3/urllib3/poolmanager.py", line 244, in urlopen
    response = conn.urlopen(method, u.request_uri, **kw)
  File "/Users/miklash90/projects/lessons1/env/lib/python3.5/site-packages/telegram/vendor/ptb_urllib3/urllib3/connectionpool.py", line 666, in urlopen
    _stacktrace=sys.exc_info()[2])
  File "/Users/miklash90/projects/lessons1/env/lib/python3.5/site-packages/telegram/vendor/ptb_urllib3/urllib3/util/retry.py", line 347, in increment
    raise six.reraise(type(error), error, _stacktrace)
  File "/Users/miklash90/projects/lessons1/env/lib/python3.5/site-packages/telegram/vendor/ptb_urllib3/urllib3/packages/six.py", line 686, in reraise
    raise value
  File "/Users/miklash90/projects/lessons1/env/lib/python3.5/site-packages/telegram/vendor/ptb_urllib3/urllib3/connectionpool.py", line 617, in urlopen
    chunked=chunked)
  File "/Users/miklash90/projects/lessons1/env/lib/python3.5/site-packages/telegram/vendor/ptb_urllib3/urllib3/connectionpool.py", line 405, in _make_request
    exc_cls=ReadTimeoutError)
  File "/Users/miklash90/projects/lessons1/env/lib/python3.5/site-packages/telegram/vendor/ptb_urllib3/urllib3/connectionpool.py", line 321, in _raise_timeout
    raise exc_cls(*args)
telegram.vendor.ptb_urllib3.urllib3.exceptions.ReadTimeoutError: HTTPSConnectionPool(host='api.telegram.org', port=443): Read timed out. (read timeout=12.0)

During handling of the above exception, another exception occurred:

Traceback (most recent call last):
  File "/Users/miklash90/projects/lessons1/env/lib/python3.5/site-packages/telegram/ext/updater.py", line 286, in _start_polling
    allowed_updates=allowed_updates)
  File "/Users/miklash90/projects/lessons1/env/lib/python3.5/site-packages/telegram/bot.py", line 60, in decorator
    result = func(self, *args, **kwargs)
  File "/Users/miklash90/projects/lessons1/env/lib/python3.5/site-packages/telegram/bot.py", line 1720, in get_updates
    result = self._request.post(url, data, timeout=float(read_latency) + float(timeout))
  File "/Users/miklash90/projects/lessons1/env/lib/python3.5/site-packages/telegram/utils/request.py", line 272, in post
    **urlopen_kwargs)
  File "/Users/miklash90/projects/lessons1/env/lib/python3.5/site-packages/telegram/utils/request.py", line 192, in _request_wrapper
    raise TimedOut()
telegram.error.TimedOut: Timed out
telegram.ext.updater - ERROR - Error while getting Updates: Timed out
telegram.ext.dispatcher - ERROR - No error handlers are registered, logging exception...
Traceback (most recent call last):
  File "/Users/miklash90/projects/lessons1/env/lib/python3.5/site-packages/telegram/vendor/ptb_urllib3/urllib3/connectionpool.py", line 402, in _make_request
    six.raise_from(e, None)
  File "<string>", line 2, in raise_from
  File "/Users/miklash90/projects/lessons1/env/lib/python3.5/site-packages/telegram/vendor/ptb_urllib3/urllib3/connectionpool.py", line 398, in _make_request
    httplib_response = conn.getresponse()
  File "/Library/Frameworks/Python.framework/Versions/3.5/lib/python3.5/http/client.py", line 1198, in getresponse
    response.begin()
  File "/Library/Frameworks/Python.framework/Versions/3.5/lib/python3.5/http/client.py", line 297, in begin
    version, status, reason = self._read_status()
  File "/Library/Frameworks/Python.framework/Versions/3.5/lib/python3.5/http/client.py", line 258, in _read_status
    line = str(self.fp.readline(_MAXLINE + 1), "iso-8859-1")
  File "/Library/Frameworks/Python.framework/Versions/3.5/lib/python3.5/socket.py", line 576, in readinto
    return self._sock.recv_into(b)
  File "/Library/Frameworks/Python.framework/Versions/3.5/lib/python3.5/ssl.py", line 937, in recv_into
    return self.read(nbytes, buffer)
  File "/Library/Frameworks/Python.framework/Versions/3.5/lib/python3.5/ssl.py", line 799, in read
    return self._sslobj.read(len, buffer)
  File "/Library/Frameworks/Python.framework/Versions/3.5/lib/python3.5/ssl.py", line 583, in read
    v = self._sslobj.read(len, buffer)
socket.timeout: The read operation timed out

During handling of the above exception, another exception occurred:

Traceback (most recent call last):
  File "/Users/miklash90/projects/lessons1/env/lib/python3.5/site-packages/telegram/utils/request.py", line 190, in _request_wrapper
    resp = self._con_pool.request(*args, **kwargs)
  File "/Users/miklash90/projects/lessons1/env/lib/python3.5/site-packages/telegram/vendor/ptb_urllib3/urllib3/request.py", line 70, in request
    **urlopen_kw)
  File "/Users/miklash90/projects/lessons1/env/lib/python3.5/site-packages/telegram/vendor/ptb_urllib3/urllib3/request.py", line 148, in request_encode_body
    return self.urlopen(method, url, **extra_kw)
  File "/Users/miklash90/projects/lessons1/env/lib/python3.5/site-packages/telegram/vendor/ptb_urllib3/urllib3/poolmanager.py", line 244, in urlopen
    response = conn.urlopen(method, u.request_uri, **kw)
  File "/Users/miklash90/projects/lessons1/env/lib/python3.5/site-packages/telegram/vendor/ptb_urllib3/urllib3/connectionpool.py", line 666, in urlopen
    _stacktrace=sys.exc_info()[2])
  File "/Users/miklash90/projects/lessons1/env/lib/python3.5/site-packages/telegram/vendor/ptb_urllib3/urllib3/util/retry.py", line 347, in increment
    raise six.reraise(type(error), error, _stacktrace)
  File "/Users/miklash90/projects/lessons1/env/lib/python3.5/site-packages/telegram/vendor/ptb_urllib3/urllib3/packages/six.py", line 686, in reraise
    raise value
  File "/Users/miklash90/projects/lessons1/env/lib/python3.5/site-packages/telegram/vendor/ptb_urllib3/urllib3/connectionpool.py", line 617, in urlopen
    chunked=chunked)
  File "/Users/miklash90/projects/lessons1/env/lib/python3.5/site-packages/telegram/vendor/ptb_urllib3/urllib3/connectionpool.py", line 405, in _make_request
    exc_cls=ReadTimeoutError)
  File "/Users/miklash90/projects/lessons1/env/lib/python3.5/site-packages/telegram/vendor/ptb_urllib3/urllib3/connectionpool.py", line 321, in _raise_timeout
    raise exc_cls(*args)
telegram.vendor.ptb_urllib3.urllib3.exceptions.ReadTimeoutError: HTTPSConnectionPool(host='api.telegram.org', port=443): Read timed out. (read timeout=12.0)

During handling of the above exception, another exception occurred:

Traceback (most recent call last):
  File "/Users/miklash90/projects/lessons1/env/lib/python3.5/site-packages/telegram/ext/updater.py", line 286, in _start_polling
    allowed_updates=allowed_updates)
  File "/Users/miklash90/projects/lessons1/env/lib/python3.5/site-packages/telegram/bot.py", line 60, in decorator
    result = func(self, *args, **kwargs)
  File "/Users/miklash90/projects/lessons1/env/lib/python3.5/site-packages/telegram/bot.py", line 1720, in get_updates
    result = self._request.post(url, data, timeout=float(read_latency) + float(timeout))
  File "/Users/miklash90/projects/lessons1/env/lib/python3.5/site-packages/telegram/utils/request.py", line 272, in post
    **urlopen_kwargs)
  File "/Users/miklash90/projects/lessons1/env/lib/python3.5/site-packages/telegram/utils/request.py", line 192, in _request_wrapper
    raise TimedOut()
telegram.error.TimedOut: Timed out
telegram.ext.updater - ERROR - Error while getting Updates: Timed out
telegram.ext.dispatcher - ERROR - No error handlers are registered, logging exception...
Traceback (most recent call last):
  File "/Users/miklash90/projects/lessons1/env/lib/python3.5/site-packages/telegram/vendor/ptb_urllib3/urllib3/connectionpool.py", line 402, in _make_request
    six.raise_from(e, None)
  File "<string>", line 2, in raise_from
  File "/Users/miklash90/projects/lessons1/env/lib/python3.5/site-packages/telegram/vendor/ptb_urllib3/urllib3/connectionpool.py", line 398, in _make_request
    httplib_response = conn.getresponse()
  File "/Library/Frameworks/Python.framework/Versions/3.5/lib/python3.5/http/client.py", line 1198, in getresponse
    response.begin()
  File "/Library/Frameworks/Python.framework/Versions/3.5/lib/python3.5/http/client.py", line 297, in begin
    version, status, reason = self._read_status()
  File "/Library/Frameworks/Python.framework/Versions/3.5/lib/python3.5/http/client.py", line 258, in _read_status
    line = str(self.fp.readline(_MAXLINE + 1), "iso-8859-1")
  File "/Library/Frameworks/Python.framework/Versions/3.5/lib/python3.5/socket.py", line 576, in readinto
    return self._sock.recv_into(b)
  File "/Library/Frameworks/Python.framework/Versions/3.5/lib/python3.5/ssl.py", line 937, in recv_into
    return self.read(nbytes, buffer)
  File "/Library/Frameworks/Python.framework/Versions/3.5/lib/python3.5/ssl.py", line 799, in read
    return self._sslobj.read(len, buffer)
  File "/Library/Frameworks/Python.framework/Versions/3.5/lib/python3.5/ssl.py", line 583, in read
    v = self._sslobj.read(len, buffer)
socket.timeout: The read operation timed out

During handling of the above exception, another exception occurred:

Traceback (most recent call last):
  File "/Users/miklash90/projects/lessons1/env/lib/python3.5/site-packages/telegram/utils/request.py", line 190, in _request_wrapper
    resp = self._con_pool.request(*args, **kwargs)
  File "/Users/miklash90/projects/lessons1/env/lib/python3.5/site-packages/telegram/vendor/ptb_urllib3/urllib3/request.py", line 70, in request
    **urlopen_kw)
  File "/Users/miklash90/projects/lessons1/env/lib/python3.5/site-packages/telegram/vendor/ptb_urllib3/urllib3/request.py", line 148, in request_encode_body
    return self.urlopen(method, url, **extra_kw)
  File "/Users/miklash90/projects/lessons1/env/lib/python3.5/site-packages/telegram/vendor/ptb_urllib3/urllib3/poolmanager.py", line 244, in urlopen
    response = conn.urlopen(method, u.request_uri, **kw)
  File "/Users/miklash90/projects/lessons1/env/lib/python3.5/site-packages/telegram/vendor/ptb_urllib3/urllib3/connectionpool.py", line 666, in urlopen
    _stacktrace=sys.exc_info()[2])
  File "/Users/miklash90/projects/lessons1/env/lib/python3.5/site-packages/telegram/vendor/ptb_urllib3/urllib3/util/retry.py", line 347, in increment
    raise six.reraise(type(error), error, _stacktrace)
  File "/Users/miklash90/projects/lessons1/env/lib/python3.5/site-packages/telegram/vendor/ptb_urllib3/urllib3/packages/six.py", line 686, in reraise
    raise value
  File "/Users/miklash90/projects/lessons1/env/lib/python3.5/site-packages/telegram/vendor/ptb_urllib3/urllib3/connectionpool.py", line 617, in urlopen
    chunked=chunked)
  File "/Users/miklash90/projects/lessons1/env/lib/python3.5/site-packages/telegram/vendor/ptb_urllib3/urllib3/connectionpool.py", line 405, in _make_request
    exc_cls=ReadTimeoutError)
  File "/Users/miklash90/projects/lessons1/env/lib/python3.5/site-packages/telegram/vendor/ptb_urllib3/urllib3/connectionpool.py", line 321, in _raise_timeout
    raise exc_cls(*args)
telegram.vendor.ptb_urllib3.urllib3.exceptions.ReadTimeoutError: HTTPSConnectionPool(host='api.telegram.org', port=443): Read timed out. (read timeout=12.0)

During handling of the above exception, another exception occurred:

Traceback (most recent call last):
  File "/Users/miklash90/projects/lessons1/env/lib/python3.5/site-packages/telegram/ext/updater.py", line 286, in _start_polling
    allowed_updates=allowed_updates)
  File "/Users/miklash90/projects/lessons1/env/lib/python3.5/site-packages/telegram/bot.py", line 60, in decorator
    result = func(self, *args, **kwargs)
  File "/Users/miklash90/projects/lessons1/env/lib/python3.5/site-packages/telegram/bot.py", line 1720, in get_updates
    result = self._request.post(url, data, timeout=float(read_latency) + float(timeout))
  File "/Users/miklash90/projects/lessons1/env/lib/python3.5/site-packages/telegram/utils/request.py", line 272, in post
    **urlopen_kwargs)
  File "/Users/miklash90/projects/lessons1/env/lib/python3.5/site-packages/telegram/utils/request.py", line 192, in _request_wrapper
    raise TimedOut()
telegram.error.TimedOut: Timed out
telegram.ext.updater - ERROR - Error while getting Updates: Timed out
telegram.ext.dispatcher - ERROR - No error handlers are registered, logging exception...
Traceback (most recent call last):
  File "/Users/miklash90/projects/lessons1/env/lib/python3.5/site-packages/telegram/vendor/ptb_urllib3/urllib3/connectionpool.py", line 402, in _make_request
    six.raise_from(e, None)
  File "<string>", line 2, in raise_from
  File "/Users/miklash90/projects/lessons1/env/lib/python3.5/site-packages/telegram/vendor/ptb_urllib3/urllib3/connectionpool.py", line 398, in _make_request
    httplib_response = conn.getresponse()
  File "/Library/Frameworks/Python.framework/Versions/3.5/lib/python3.5/http/client.py", line 1198, in getresponse
    response.begin()
  File "/Library/Frameworks/Python.framework/Versions/3.5/lib/python3.5/http/client.py", line 297, in begin
    version, status, reason = self._read_status()
  File "/Library/Frameworks/Python.framework/Versions/3.5/lib/python3.5/http/client.py", line 258, in _read_status
    line = str(self.fp.readline(_MAXLINE + 1), "iso-8859-1")
  File "/Library/Frameworks/Python.framework/Versions/3.5/lib/python3.5/socket.py", line 576, in readinto
    return self._sock.recv_into(b)
  File "/Library/Frameworks/Python.framework/Versions/3.5/lib/python3.5/ssl.py", line 937, in recv_into
    return self.read(nbytes, buffer)
  File "/Library/Frameworks/Python.framework/Versions/3.5/lib/python3.5/ssl.py", line 799, in read
    return self._sslobj.read(len, buffer)
  File "/Library/Frameworks/Python.framework/Versions/3.5/lib/python3.5/ssl.py", line 583, in read
    v = self._sslobj.read(len, buffer)
socket.timeout: The read operation timed out

During handling of the above exception, another exception occurred:

Traceback (most recent call last):
  File "/Users/miklash90/projects/lessons1/env/lib/python3.5/site-packages/telegram/utils/request.py", line 190, in _request_wrapper
    resp = self._con_pool.request(*args, **kwargs)
  File "/Users/miklash90/projects/lessons1/env/lib/python3.5/site-packages/telegram/vendor/ptb_urllib3/urllib3/request.py", line 70, in request
    **urlopen_kw)
  File "/Users/miklash90/projects/lessons1/env/lib/python3.5/site-packages/telegram/vendor/ptb_urllib3/urllib3/request.py", line 148, in request_encode_body
    return self.urlopen(method, url, **extra_kw)
  File "/Users/miklash90/projects/lessons1/env/lib/python3.5/site-packages/telegram/vendor/ptb_urllib3/urllib3/poolmanager.py", line 244, in urlopen
    response = conn.urlopen(method, u.request_uri, **kw)
  File "/Users/miklash90/projects/lessons1/env/lib/python3.5/site-packages/telegram/vendor/ptb_urllib3/urllib3/connectionpool.py", line 666, in urlopen
    _stacktrace=sys.exc_info()[2])
  File "/Users/miklash90/projects/lessons1/env/lib/python3.5/site-packages/telegram/vendor/ptb_urllib3/urllib3/util/retry.py", line 347, in increment
    raise six.reraise(type(error), error, _stacktrace)
  File "/Users/miklash90/projects/lessons1/env/lib/python3.5/site-packages/telegram/vendor/ptb_urllib3/urllib3/packages/six.py", line 686, in reraise
    raise value
  File "/Users/miklash90/projects/lessons1/env/lib/python3.5/site-packages/telegram/vendor/ptb_urllib3/urllib3/connectionpool.py", line 617, in urlopen
    chunked=chunked)
  File "/Users/miklash90/projects/lessons1/env/lib/python3.5/site-packages/telegram/vendor/ptb_urllib3/urllib3/connectionpool.py", line 405, in _make_request
    exc_cls=ReadTimeoutError)
  File "/Users/miklash90/projects/lessons1/env/lib/python3.5/site-packages/telegram/vendor/ptb_urllib3/urllib3/connectionpool.py", line 321, in _raise_timeout
    raise exc_cls(*args)
telegram.vendor.ptb_urllib3.urllib3.exceptions.ReadTimeoutError: HTTPSConnectionPool(host='api.telegram.org', port=443): Read timed out. (read timeout=12.0)

During handling of the above exception, another exception occurred:

Traceback (most recent call last):
  File "/Users/miklash90/projects/lessons1/env/lib/python3.5/site-packages/telegram/ext/updater.py", line 286, in _start_polling
    allowed_updates=allowed_updates)
  File "/Users/miklash90/projects/lessons1/env/lib/python3.5/site-packages/telegram/bot.py", line 60, in decorator
    result = func(self, *args, **kwargs)
  File "/Users/miklash90/projects/lessons1/env/lib/python3.5/site-packages/telegram/bot.py", line 1720, in get_updates
    result = self._request.post(url, data, timeout=float(read_latency) + float(timeout))
  File "/Users/miklash90/projects/lessons1/env/lib/python3.5/site-packages/telegram/utils/request.py", line 272, in post
    **urlopen_kwargs)
  File "/Users/miklash90/projects/lessons1/env/lib/python3.5/site-packages/telegram/utils/request.py", line 192, in _request_wrapper
    raise TimedOut()
telegram.error.TimedOut: Timed out
telegram.ext.updater - ERROR - Error while getting Updates: Timed out
telegram.ext.dispatcher - ERROR - No error handlers are registered, logging exception...
Traceback (most recent call last):
  File "/Users/miklash90/projects/lessons1/env/lib/python3.5/site-packages/telegram/vendor/ptb_urllib3/urllib3/connectionpool.py", line 402, in _make_request
    six.raise_from(e, None)
  File "<string>", line 2, in raise_from
  File "/Users/miklash90/projects/lessons1/env/lib/python3.5/site-packages/telegram/vendor/ptb_urllib3/urllib3/connectionpool.py", line 398, in _make_request
    httplib_response = conn.getresponse()
  File "/Library/Frameworks/Python.framework/Versions/3.5/lib/python3.5/http/client.py", line 1198, in getresponse
    response.begin()
  File "/Library/Frameworks/Python.framework/Versions/3.5/lib/python3.5/http/client.py", line 297, in begin
    version, status, reason = self._read_status()
  File "/Library/Frameworks/Python.framework/Versions/3.5/lib/python3.5/http/client.py", line 258, in _read_status
    line = str(self.fp.readline(_MAXLINE + 1), "iso-8859-1")
  File "/Library/Frameworks/Python.framework/Versions/3.5/lib/python3.5/socket.py", line 576, in readinto
    return self._sock.recv_into(b)
  File "/Library/Frameworks/Python.framework/Versions/3.5/lib/python3.5/ssl.py", line 937, in recv_into
    return self.read(nbytes, buffer)
  File "/Library/Frameworks/Python.framework/Versions/3.5/lib/python3.5/ssl.py", line 799, in read
    return self._sslobj.read(len, buffer)
  File "/Library/Frameworks/Python.framework/Versions/3.5/lib/python3.5/ssl.py", line 583, in read
    v = self._sslobj.read(len, buffer)
socket.timeout: The read operation timed out

During handling of the above exception, another exception occurred:

Traceback (most recent call last):
  File "/Users/miklash90/projects/lessons1/env/lib/python3.5/site-packages/telegram/utils/request.py", line 190, in _request_wrapper
    resp = self._con_pool.request(*args, **kwargs)
  File "/Users/miklash90/projects/lessons1/env/lib/python3.5/site-packages/telegram/vendor/ptb_urllib3/urllib3/request.py", line 70, in request
    **urlopen_kw)
  File "/Users/miklash90/projects/lessons1/env/lib/python3.5/site-packages/telegram/vendor/ptb_urllib3/urllib3/request.py", line 148, in request_encode_body
    return self.urlopen(method, url, **extra_kw)
  File "/Users/miklash90/projects/lessons1/env/lib/python3.5/site-packages/telegram/vendor/ptb_urllib3/urllib3/poolmanager.py", line 244, in urlopen
    response = conn.urlopen(method, u.request_uri, **kw)
  File "/Users/miklash90/projects/lessons1/env/lib/python3.5/site-packages/telegram/vendor/ptb_urllib3/urllib3/connectionpool.py", line 666, in urlopen
    _stacktrace=sys.exc_info()[2])
  File "/Users/miklash90/projects/lessons1/env/lib/python3.5/site-packages/telegram/vendor/ptb_urllib3/urllib3/util/retry.py", line 347, in increment
    raise six.reraise(type(error), error, _stacktrace)
  File "/Users/miklash90/projects/lessons1/env/lib/python3.5/site-packages/telegram/vendor/ptb_urllib3/urllib3/packages/six.py", line 686, in reraise
    raise value
  File "/Users/miklash90/projects/lessons1/env/lib/python3.5/site-packages/telegram/vendor/ptb_urllib3/urllib3/connectionpool.py", line 617, in urlopen
    chunked=chunked)
  File "/Users/miklash90/projects/lessons1/env/lib/python3.5/site-packages/telegram/vendor/ptb_urllib3/urllib3/connectionpool.py", line 405, in _make_request
    exc_cls=ReadTimeoutError)
  File "/Users/miklash90/projects/lessons1/env/lib/python3.5/site-packages/telegram/vendor/ptb_urllib3/urllib3/connectionpool.py", line 321, in _raise_timeout
    raise exc_cls(*args)
telegram.vendor.ptb_urllib3.urllib3.exceptions.ReadTimeoutError: HTTPSConnectionPool(host='api.telegram.org', port=443): Read timed out. (read timeout=12.0)

During handling of the above exception, another exception occurred:

Traceback (most recent call last):
  File "/Users/miklash90/projects/lessons1/env/lib/python3.5/site-packages/telegram/ext/updater.py", line 286, in _start_polling
    allowed_updates=allowed_updates)
  File "/Users/miklash90/projects/lessons1/env/lib/python3.5/site-packages/telegram/bot.py", line 60, in decorator
    result = func(self, *args, **kwargs)
  File "/Users/miklash90/projects/lessons1/env/lib/python3.5/site-packages/telegram/bot.py", line 1720, in get_updates
    result = self._request.post(url, data, timeout=float(read_latency) + float(timeout))
  File "/Users/miklash90/projects/lessons1/env/lib/python3.5/site-packages/telegram/utils/request.py", line 272, in post
    **urlopen_kwargs)
  File "/Users/miklash90/projects/lessons1/env/lib/python3.5/site-packages/telegram/utils/request.py", line 192, in _request_wrapper
    raise TimedOut()
telegram.error.TimedOut: Timed out
telegram.ext.updater - ERROR - Error while getting Updates: Timed out
telegram.ext.dispatcher - ERROR - No error handlers are registered, logging exception...
Traceback (most recent call last):
  File "/Users/miklash90/projects/lessons1/env/lib/python3.5/site-packages/telegram/vendor/ptb_urllib3/urllib3/connectionpool.py", line 402, in _make_request
    six.raise_from(e, None)
  File "<string>", line 2, in raise_from
  File "/Users/miklash90/projects/lessons1/env/lib/python3.5/site-packages/telegram/vendor/ptb_urllib3/urllib3/connectionpool.py", line 398, in _make_request
    httplib_response = conn.getresponse()
  File "/Library/Frameworks/Python.framework/Versions/3.5/lib/python3.5/http/client.py", line 1198, in getresponse
    response.begin()
  File "/Library/Frameworks/Python.framework/Versions/3.5/lib/python3.5/http/client.py", line 297, in begin
    version, status, reason = self._read_status()
  File "/Library/Frameworks/Python.framework/Versions/3.5/lib/python3.5/http/client.py", line 258, in _read_status
    line = str(self.fp.readline(_MAXLINE + 1), "iso-8859-1")
  File "/Library/Frameworks/Python.framework/Versions/3.5/lib/python3.5/socket.py", line 576, in readinto
    return self._sock.recv_into(b)
  File "/Library/Frameworks/Python.framework/Versions/3.5/lib/python3.5/ssl.py", line 937, in recv_into
    return self.read(nbytes, buffer)
  File "/Library/Frameworks/Python.framework/Versions/3.5/lib/python3.5/ssl.py", line 799, in read
    return self._sslobj.read(len, buffer)
  File "/Library/Frameworks/Python.framework/Versions/3.5/lib/python3.5/ssl.py", line 583, in read
    v = self._sslobj.read(len, buffer)
socket.timeout: The read operation timed out

During handling of the above exception, another exception occurred:

Traceback (most recent call last):
  File "/Users/miklash90/projects/lessons1/env/lib/python3.5/site-packages/telegram/utils/request.py", line 190, in _request_wrapper
    resp = self._con_pool.request(*args, **kwargs)
  File "/Users/miklash90/projects/lessons1/env/lib/python3.5/site-packages/telegram/vendor/ptb_urllib3/urllib3/request.py", line 70, in request
    **urlopen_kw)
  File "/Users/miklash90/projects/lessons1/env/lib/python3.5/site-packages/telegram/vendor/ptb_urllib3/urllib3/request.py", line 148, in request_encode_body
    return self.urlopen(method, url, **extra_kw)
  File "/Users/miklash90/projects/lessons1/env/lib/python3.5/site-packages/telegram/vendor/ptb_urllib3/urllib3/poolmanager.py", line 244, in urlopen
    response = conn.urlopen(method, u.request_uri, **kw)
  File "/Users/miklash90/projects/lessons1/env/lib/python3.5/site-packages/telegram/vendor/ptb_urllib3/urllib3/connectionpool.py", line 666, in urlopen
    _stacktrace=sys.exc_info()[2])
  File "/Users/miklash90/projects/lessons1/env/lib/python3.5/site-packages/telegram/vendor/ptb_urllib3/urllib3/util/retry.py", line 347, in increment
    raise six.reraise(type(error), error, _stacktrace)
  File "/Users/miklash90/projects/lessons1/env/lib/python3.5/site-packages/telegram/vendor/ptb_urllib3/urllib3/packages/six.py", line 686, in reraise
    raise value
  File "/Users/miklash90/projects/lessons1/env/lib/python3.5/site-packages/telegram/vendor/ptb_urllib3/urllib3/connectionpool.py", line 617, in urlopen
    chunked=chunked)
  File "/Users/miklash90/projects/lessons1/env/lib/python3.5/site-packages/telegram/vendor/ptb_urllib3/urllib3/connectionpool.py", line 405, in _make_request
    exc_cls=ReadTimeoutError)
  File "/Users/miklash90/projects/lessons1/env/lib/python3.5/site-packages/telegram/vendor/ptb_urllib3/urllib3/connectionpool.py", line 321, in _raise_timeout
    raise exc_cls(*args)
telegram.vendor.ptb_urllib3.urllib3.exceptions.ReadTimeoutError: HTTPSConnectionPool(host='api.telegram.org', port=443): Read timed out. (read timeout=12.0)

During handling of the above exception, another exception occurred:

Traceback (most recent call last):
  File "/Users/miklash90/projects/lessons1/env/lib/python3.5/site-packages/telegram/ext/updater.py", line 286, in _start_polling
    allowed_updates=allowed_updates)
  File "/Users/miklash90/projects/lessons1/env/lib/python3.5/site-packages/telegram/bot.py", line 60, in decorator
    result = func(self, *args, **kwargs)
  File "/Users/miklash90/projects/lessons1/env/lib/python3.5/site-packages/telegram/bot.py", line 1720, in get_updates
    result = self._request.post(url, data, timeout=float(read_latency) + float(timeout))
  File "/Users/miklash90/projects/lessons1/env/lib/python3.5/site-packages/telegram/utils/request.py", line 272, in post
    **urlopen_kwargs)
  File "/Users/miklash90/projects/lessons1/env/lib/python3.5/site-packages/telegram/utils/request.py", line 192, in _request_wrapper
    raise TimedOut()
telegram.error.TimedOut: Timed out
telegram.vendor.ptb_urllib3.urllib3.connectionpool - WARNING - Retrying (Retry(total=2, connect=None, read=None, redirect=None)) after connection broken by 'NewConnectionError('<telegram.vendor.ptb_urllib3.urllib3.connection.VerifiedHTTPSConnection object at 0x110ab5898>: Failed to establish a new connection: [Errno 8] nodename nor servname provided, or not known',)': /bot536305288:AAGTKLPlZytJlj-QUQFnlJgf0h8aKleZQ0E/getUpdates
telegram.vendor.ptb_urllib3.urllib3.connectionpool - WARNING - Retrying (Retry(total=1, connect=None, read=None, redirect=None)) after connection broken by 'NewConnectionError('<telegram.vendor.ptb_urllib3.urllib3.connection.VerifiedHTTPSConnection object at 0x110ab54e0>: Failed to establish a new connection: [Errno 8] nodename nor servname provided, or not known',)': /bot536305288:AAGTKLPlZytJlj-QUQFnlJgf0h8aKleZQ0E/getUpdates
telegram.vendor.ptb_urllib3.urllib3.connectionpool - WARNING - Retrying (Retry(total=0, connect=None, read=None, redirect=None)) after connection broken by 'NewConnectionError('<telegram.vendor.ptb_urllib3.urllib3.connection.VerifiedHTTPSConnection object at 0x110ab5c50>: Failed to establish a new connection: [Errno 8] nodename nor servname provided, or not known',)': /bot536305288:AAGTKLPlZytJlj-QUQFnlJgf0h8aKleZQ0E/getUpdates
telegram.ext.updater - ERROR - Error while getting Updates: urllib3 HTTPError HTTPSConnectionPool(host='api.telegram.org', port=443): Max retries exceeded with url: /bot536305288:AAGTKLPlZytJlj-QUQFnlJgf0h8aKleZQ0E/getUpdates (Caused by NewConnectionError('<telegram.vendor.ptb_urllib3.urllib3.connection.VerifiedHTTPSConnection object at 0x110ab5940>: Failed to establish a new connection: [Errno 8] nodename nor servname provided, or not known',))
telegram.ext.dispatcher - ERROR - No error handlers are registered, logging exception...
Traceback (most recent call last):
  File "/Users/miklash90/projects/lessons1/env/lib/python3.5/site-packages/telegram/vendor/ptb_urllib3/urllib3/connection.py", line 141, in _new_conn
    (self.host, self.port), self.timeout, **extra_kw)
  File "/Users/miklash90/projects/lessons1/env/lib/python3.5/site-packages/telegram/vendor/ptb_urllib3/urllib3/util/connection.py", line 60, in create_connection
    for res in socket.getaddrinfo(host, port, family, socket.SOCK_STREAM):
  File "/Library/Frameworks/Python.framework/Versions/3.5/lib/python3.5/socket.py", line 733, in getaddrinfo
    for res in _socket.getaddrinfo(host, port, family, type, proto, flags):
socket.gaierror: [Errno 8] nodename nor servname provided, or not known

During handling of the above exception, another exception occurred:

Traceback (most recent call last):
  File "/Users/miklash90/projects/lessons1/env/lib/python3.5/site-packages/telegram/vendor/ptb_urllib3/urllib3/connectionpool.py", line 617, in urlopen
    chunked=chunked)
  File "/Users/miklash90/projects/lessons1/env/lib/python3.5/site-packages/telegram/vendor/ptb_urllib3/urllib3/connectionpool.py", line 360, in _make_request
    self._validate_conn(conn)
  File "/Users/miklash90/projects/lessons1/env/lib/python3.5/site-packages/telegram/vendor/ptb_urllib3/urllib3/connectionpool.py", line 857, in _validate_conn
    super(HTTPSConnectionPool, self)._validate_conn(conn)
  File "/Users/miklash90/projects/lessons1/env/lib/python3.5/site-packages/telegram/vendor/ptb_urllib3/urllib3/connectionpool.py", line 289, in _validate_conn
    conn.connect()
  File "/Users/miklash90/projects/lessons1/env/lib/python3.5/site-packages/telegram/vendor/ptb_urllib3/urllib3/connection.py", line 284, in connect
    conn = self._new_conn()
  File "/Users/miklash90/projects/lessons1/env/lib/python3.5/site-packages/telegram/vendor/ptb_urllib3/urllib3/connection.py", line 150, in _new_conn
    self, "Failed to establish a new connection: %s" % e)
telegram.vendor.ptb_urllib3.urllib3.exceptions.NewConnectionError: <telegram.vendor.ptb_urllib3.urllib3.connection.VerifiedHTTPSConnection object at 0x110ab5940>: Failed to establish a new connection: [Errno 8] nodename nor servname provided, or not known

During handling of the above exception, another exception occurred:

Traceback (most recent call last):
  File "/Users/miklash90/projects/lessons1/env/lib/python3.5/site-packages/telegram/utils/request.py", line 190, in _request_wrapper
    resp = self._con_pool.request(*args, **kwargs)
  File "/Users/miklash90/projects/lessons1/env/lib/python3.5/site-packages/telegram/vendor/ptb_urllib3/urllib3/request.py", line 70, in request
    **urlopen_kw)
  File "/Users/miklash90/projects/lessons1/env/lib/python3.5/site-packages/telegram/vendor/ptb_urllib3/urllib3/request.py", line 148, in request_encode_body
    return self.urlopen(method, url, **extra_kw)
  File "/Users/miklash90/projects/lessons1/env/lib/python3.5/site-packages/telegram/vendor/ptb_urllib3/urllib3/poolmanager.py", line 244, in urlopen
    response = conn.urlopen(method, u.request_uri, **kw)
  File "/Users/miklash90/projects/lessons1/env/lib/python3.5/site-packages/telegram/vendor/ptb_urllib3/urllib3/connectionpool.py", line 695, in urlopen
    **response_kw)
  File "/Users/miklash90/projects/lessons1/env/lib/python3.5/site-packages/telegram/vendor/ptb_urllib3/urllib3/connectionpool.py", line 695, in urlopen
    **response_kw)
  File "/Users/miklash90/projects/lessons1/env/lib/python3.5/site-packages/telegram/vendor/ptb_urllib3/urllib3/connectionpool.py", line 695, in urlopen
    **response_kw)
  File "/Users/miklash90/projects/lessons1/env/lib/python3.5/site-packages/telegram/vendor/ptb_urllib3/urllib3/connectionpool.py", line 666, in urlopen
    _stacktrace=sys.exc_info()[2])
  File "/Users/miklash90/projects/lessons1/env/lib/python3.5/site-packages/telegram/vendor/ptb_urllib3/urllib3/util/retry.py", line 376, in increment
    raise MaxRetryError(_pool, url, error or ResponseError(cause))
telegram.vendor.ptb_urllib3.urllib3.exceptions.MaxRetryError: HTTPSConnectionPool(host='api.telegram.org', port=443): Max retries exceeded with url: /bot536305288:AAGTKLPlZytJlj-QUQFnlJgf0h8aKleZQ0E/getUpdates (Caused by NewConnectionError('<telegram.vendor.ptb_urllib3.urllib3.connection.VerifiedHTTPSConnection object at 0x110ab5940>: Failed to establish a new connection: [Errno 8] nodename nor servname provided, or not known',))

During handling of the above exception, another exception occurred:

Traceback (most recent call last):
  File "/Users/miklash90/projects/lessons1/env/lib/python3.5/site-packages/telegram/ext/updater.py", line 286, in _start_polling
    allowed_updates=allowed_updates)
  File "/Users/miklash90/projects/lessons1/env/lib/python3.5/site-packages/telegram/bot.py", line 60, in decorator
    result = func(self, *args, **kwargs)
  File "/Users/miklash90/projects/lessons1/env/lib/python3.5/site-packages/telegram/bot.py", line 1720, in get_updates
    result = self._request.post(url, data, timeout=float(read_latency) + float(timeout))
  File "/Users/miklash90/projects/lessons1/env/lib/python3.5/site-packages/telegram/utils/request.py", line 272, in post
    **urlopen_kwargs)
  File "/Users/miklash90/projects/lessons1/env/lib/python3.5/site-packages/telegram/utils/request.py", line 196, in _request_wrapper
    raise NetworkError('urllib3 HTTPError {0}'.format(error))
telegram.error.NetworkError: urllib3 HTTPError HTTPSConnectionPool(host='api.telegram.org', port=443): Max retries exceeded with url: /bot536305288:AAGTKLPlZytJlj-QUQFnlJgf0h8aKleZQ0E/getUpdates (Caused by NewConnectionError('<telegram.vendor.ptb_urllib3.urllib3.connection.VerifiedHTTPSConnection object at 0x110ab5940>: Failed to establish a new connection: [Errno 8] nodename nor servname provided, or not known',))
telegram.vendor.ptb_urllib3.urllib3.connectionpool - WARNING - Retrying (Retry(total=2, connect=None, read=None, redirect=None)) after connection broken by 'NewConnectionError('<telegram.vendor.ptb_urllib3.urllib3.connection.VerifiedHTTPSConnection object at 0x110ab5c18>: Failed to establish a new connection: [Errno 8] nodename nor servname provided, or not known',)': /bot536305288:AAGTKLPlZytJlj-QUQFnlJgf0h8aKleZQ0E/getUpdates
telegram.vendor.ptb_urllib3.urllib3.connectionpool - WARNING - Retrying (Retry(total=1, connect=None, read=None, redirect=None)) after connection broken by 'NewConnectionError('<telegram.vendor.ptb_urllib3.urllib3.connection.VerifiedHTTPSConnection object at 0x110ac6048>: Failed to establish a new connection: [Errno 8] nodename nor servname provided, or not known',)': /bot536305288:AAGTKLPlZytJlj-QUQFnlJgf0h8aKleZQ0E/getUpdates
telegram.vendor.ptb_urllib3.urllib3.connectionpool - WARNING - Retrying (Retry(total=0, connect=None, read=None, redirect=None)) after connection broken by 'NewConnectionError('<telegram.vendor.ptb_urllib3.urllib3.connection.VerifiedHTTPSConnection object at 0x110ac6080>: Failed to establish a new connection: [Errno 8] nodename nor servname provided, or not known',)': /bot536305288:AAGTKLPlZytJlj-QUQFnlJgf0h8aKleZQ0E/getUpdates
telegram.ext.updater - ERROR - Error while getting Updates: urllib3 HTTPError HTTPSConnectionPool(host='api.telegram.org', port=443): Max retries exceeded with url: /bot536305288:AAGTKLPlZytJlj-QUQFnlJgf0h8aKleZQ0E/getUpdates (Caused by NewConnectionError('<telegram.vendor.ptb_urllib3.urllib3.connection.VerifiedHTTPSConnection object at 0x110ab5518>: Failed to establish a new connection: [Errno 8] nodename nor servname provided, or not known',))
telegram.ext.dispatcher - ERROR - No error handlers are registered, logging exception...
Traceback (most recent call last):
  File "/Users/miklash90/projects/lessons1/env/lib/python3.5/site-packages/telegram/vendor/ptb_urllib3/urllib3/connection.py", line 141, in _new_conn
    (self.host, self.port), self.timeout, **extra_kw)
  File "/Users/miklash90/projects/lessons1/env/lib/python3.5/site-packages/telegram/vendor/ptb_urllib3/urllib3/util/connection.py", line 60, in create_connection
    for res in socket.getaddrinfo(host, port, family, socket.SOCK_STREAM):
  File "/Library/Frameworks/Python.framework/Versions/3.5/lib/python3.5/socket.py", line 733, in getaddrinfo
    for res in _socket.getaddrinfo(host, port, family, type, proto, flags):
socket.gaierror: [Errno 8] nodename nor servname provided, or not known

During handling of the above exception, another exception occurred:

Traceback (most recent call last):
  File "/Users/miklash90/projects/lessons1/env/lib/python3.5/site-packages/telegram/vendor/ptb_urllib3/urllib3/connectionpool.py", line 617, in urlopen
    chunked=chunked)
  File "/Users/miklash90/projects/lessons1/env/lib/python3.5/site-packages/telegram/vendor/ptb_urllib3/urllib3/connectionpool.py", line 360, in _make_request
    self._validate_conn(conn)
  File "/Users/miklash90/projects/lessons1/env/lib/python3.5/site-packages/telegram/vendor/ptb_urllib3/urllib3/connectionpool.py", line 857, in _validate_conn
    super(HTTPSConnectionPool, self)._validate_conn(conn)
  File "/Users/miklash90/projects/lessons1/env/lib/python3.5/site-packages/telegram/vendor/ptb_urllib3/urllib3/connectionpool.py", line 289, in _validate_conn
    conn.connect()
  File "/Users/miklash90/projects/lessons1/env/lib/python3.5/site-packages/telegram/vendor/ptb_urllib3/urllib3/connection.py", line 284, in connect
    conn = self._new_conn()
  File "/Users/miklash90/projects/lessons1/env/lib/python3.5/site-packages/telegram/vendor/ptb_urllib3/urllib3/connection.py", line 150, in _new_conn
    self, "Failed to establish a new connection: %s" % e)
telegram.vendor.ptb_urllib3.urllib3.exceptions.NewConnectionError: <telegram.vendor.ptb_urllib3.urllib3.connection.VerifiedHTTPSConnection object at 0x110ab5518>: Failed to establish a new connection: [Errno 8] nodename nor servname provided, or not known

During handling of the above exception, another exception occurred:

Traceback (most recent call last):
  File "/Users/miklash90/projects/lessons1/env/lib/python3.5/site-packages/telegram/utils/request.py", line 190, in _request_wrapper
    resp = self._con_pool.request(*args, **kwargs)
  File "/Users/miklash90/projects/lessons1/env/lib/python3.5/site-packages/telegram/vendor/ptb_urllib3/urllib3/request.py", line 70, in request
    **urlopen_kw)
  File "/Users/miklash90/projects/lessons1/env/lib/python3.5/site-packages/telegram/vendor/ptb_urllib3/urllib3/request.py", line 148, in request_encode_body
    return self.urlopen(method, url, **extra_kw)
  File "/Users/miklash90/projects/lessons1/env/lib/python3.5/site-packages/telegram/vendor/ptb_urllib3/urllib3/poolmanager.py", line 244, in urlopen
    response = conn.urlopen(method, u.request_uri, **kw)
  File "/Users/miklash90/projects/lessons1/env/lib/python3.5/site-packages/telegram/vendor/ptb_urllib3/urllib3/connectionpool.py", line 695, in urlopen
    **response_kw)
  File "/Users/miklash90/projects/lessons1/env/lib/python3.5/site-packages/telegram/vendor/ptb_urllib3/urllib3/connectionpool.py", line 695, in urlopen
    **response_kw)
  File "/Users/miklash90/projects/lessons1/env/lib/python3.5/site-packages/telegram/vendor/ptb_urllib3/urllib3/connectionpool.py", line 695, in urlopen
    **response_kw)
  File "/Users/miklash90/projects/lessons1/env/lib/python3.5/site-packages/telegram/vendor/ptb_urllib3/urllib3/connectionpool.py", line 666, in urlopen
    _stacktrace=sys.exc_info()[2])
  File "/Users/miklash90/projects/lessons1/env/lib/python3.5/site-packages/telegram/vendor/ptb_urllib3/urllib3/util/retry.py", line 376, in increment
    raise MaxRetryError(_pool, url, error or ResponseError(cause))
telegram.vendor.ptb_urllib3.urllib3.exceptions.MaxRetryError: HTTPSConnectionPool(host='api.telegram.org', port=443): Max retries exceeded with url: /bot536305288:AAGTKLPlZytJlj-QUQFnlJgf0h8aKleZQ0E/getUpdates (Caused by NewConnectionError('<telegram.vendor.ptb_urllib3.urllib3.connection.VerifiedHTTPSConnection object at 0x110ab5518>: Failed to establish a new connection: [Errno 8] nodename nor servname provided, or not known',))

During handling of the above exception, another exception occurred:

Traceback (most recent call last):
  File "/Users/miklash90/projects/lessons1/env/lib/python3.5/site-packages/telegram/ext/updater.py", line 286, in _start_polling
    allowed_updates=allowed_updates)
  File "/Users/miklash90/projects/lessons1/env/lib/python3.5/site-packages/telegram/bot.py", line 60, in decorator
    result = func(self, *args, **kwargs)
  File "/Users/miklash90/projects/lessons1/env/lib/python3.5/site-packages/telegram/bot.py", line 1720, in get_updates
    result = self._request.post(url, data, timeout=float(read_latency) + float(timeout))
  File "/Users/miklash90/projects/lessons1/env/lib/python3.5/site-packages/telegram/utils/request.py", line 272, in post
    **urlopen_kwargs)
  File "/Users/miklash90/projects/lessons1/env/lib/python3.5/site-packages/telegram/utils/request.py", line 196, in _request_wrapper
    raise NetworkError('urllib3 HTTPError {0}'.format(error))
telegram.error.NetworkError: urllib3 HTTPError HTTPSConnectionPool(host='api.telegram.org', port=443): Max retries exceeded with url: /bot536305288:AAGTKLPlZytJlj-QUQFnlJgf0h8aKleZQ0E/getUpdates (Caused by NewConnectionError('<telegram.vendor.ptb_urllib3.urllib3.connection.VerifiedHTTPSConnection object at 0x110ab5518>: Failed to establish a new connection: [Errno 8] nodename nor servname provided, or not known',))
telegram.ext.updater - ERROR - Error while getting Updates: Timed out
telegram.ext.dispatcher - ERROR - No error handlers are registered, logging exception...
Traceback (most recent call last):
  File "/Users/miklash90/projects/lessons1/env/lib/python3.5/site-packages/telegram/vendor/ptb_urllib3/urllib3/connectionpool.py", line 402, in _make_request
    six.raise_from(e, None)
  File "<string>", line 2, in raise_from
  File "/Users/miklash90/projects/lessons1/env/lib/python3.5/site-packages/telegram/vendor/ptb_urllib3/urllib3/connectionpool.py", line 398, in _make_request
    httplib_response = conn.getresponse()
  File "/Library/Frameworks/Python.framework/Versions/3.5/lib/python3.5/http/client.py", line 1198, in getresponse
    response.begin()
  File "/Library/Frameworks/Python.framework/Versions/3.5/lib/python3.5/http/client.py", line 297, in begin
    version, status, reason = self._read_status()
  File "/Library/Frameworks/Python.framework/Versions/3.5/lib/python3.5/http/client.py", line 258, in _read_status
    line = str(self.fp.readline(_MAXLINE + 1), "iso-8859-1")
  File "/Library/Frameworks/Python.framework/Versions/3.5/lib/python3.5/socket.py", line 576, in readinto
    return self._sock.recv_into(b)
  File "/Library/Frameworks/Python.framework/Versions/3.5/lib/python3.5/ssl.py", line 937, in recv_into
    return self.read(nbytes, buffer)
  File "/Library/Frameworks/Python.framework/Versions/3.5/lib/python3.5/ssl.py", line 799, in read
    return self._sslobj.read(len, buffer)
  File "/Library/Frameworks/Python.framework/Versions/3.5/lib/python3.5/ssl.py", line 583, in read
    v = self._sslobj.read(len, buffer)
socket.timeout: The read operation timed out

During handling of the above exception, another exception occurred:

Traceback (most recent call last):
  File "/Users/miklash90/projects/lessons1/env/lib/python3.5/site-packages/telegram/utils/request.py", line 190, in _request_wrapper
    resp = self._con_pool.request(*args, **kwargs)
  File "/Users/miklash90/projects/lessons1/env/lib/python3.5/site-packages/telegram/vendor/ptb_urllib3/urllib3/request.py", line 70, in request
    **urlopen_kw)
  File "/Users/miklash90/projects/lessons1/env/lib/python3.5/site-packages/telegram/vendor/ptb_urllib3/urllib3/request.py", line 148, in request_encode_body
    return self.urlopen(method, url, **extra_kw)
  File "/Users/miklash90/projects/lessons1/env/lib/python3.5/site-packages/telegram/vendor/ptb_urllib3/urllib3/poolmanager.py", line 244, in urlopen
    response = conn.urlopen(method, u.request_uri, **kw)
  File "/Users/miklash90/projects/lessons1/env/lib/python3.5/site-packages/telegram/vendor/ptb_urllib3/urllib3/connectionpool.py", line 666, in urlopen
    _stacktrace=sys.exc_info()[2])
  File "/Users/miklash90/projects/lessons1/env/lib/python3.5/site-packages/telegram/vendor/ptb_urllib3/urllib3/util/retry.py", line 347, in increment
    raise six.reraise(type(error), error, _stacktrace)
  File "/Users/miklash90/projects/lessons1/env/lib/python3.5/site-packages/telegram/vendor/ptb_urllib3/urllib3/packages/six.py", line 686, in reraise
    raise value
  File "/Users/miklash90/projects/lessons1/env/lib/python3.5/site-packages/telegram/vendor/ptb_urllib3/urllib3/connectionpool.py", line 617, in urlopen
    chunked=chunked)
  File "/Users/miklash90/projects/lessons1/env/lib/python3.5/site-packages/telegram/vendor/ptb_urllib3/urllib3/connectionpool.py", line 405, in _make_request
    exc_cls=ReadTimeoutError)
  File "/Users/miklash90/projects/lessons1/env/lib/python3.5/site-packages/telegram/vendor/ptb_urllib3/urllib3/connectionpool.py", line 321, in _raise_timeout
    raise exc_cls(*args)
telegram.vendor.ptb_urllib3.urllib3.exceptions.ReadTimeoutError: HTTPSConnectionPool(host='api.telegram.org', port=443): Read timed out. (read timeout=12.0)

During handling of the above exception, another exception occurred:

Traceback (most recent call last):
  File "/Users/miklash90/projects/lessons1/env/lib/python3.5/site-packages/telegram/ext/updater.py", line 286, in _start_polling
    allowed_updates=allowed_updates)
  File "/Users/miklash90/projects/lessons1/env/lib/python3.5/site-packages/telegram/bot.py", line 60, in decorator
    result = func(self, *args, **kwargs)
  File "/Users/miklash90/projects/lessons1/env/lib/python3.5/site-packages/telegram/bot.py", line 1720, in get_updates
    result = self._request.post(url, data, timeout=float(read_latency) + float(timeout))
  File "/Users/miklash90/projects/lessons1/env/lib/python3.5/site-packages/telegram/utils/request.py", line 272, in post
    **urlopen_kwargs)
  File "/Users/miklash90/projects/lessons1/env/lib/python3.5/site-packages/telegram/utils/request.py", line 192, in _request_wrapper
    raise TimedOut()
telegram.error.TimedOut: Timed out
telegram.ext.updater - ERROR - Error while getting Updates: Timed out
telegram.ext.dispatcher - ERROR - No error handlers are registered, logging exception...
Traceback (most recent call last):
  File "/Users/miklash90/projects/lessons1/env/lib/python3.5/site-packages/telegram/vendor/ptb_urllib3/urllib3/connectionpool.py", line 402, in _make_request
    six.raise_from(e, None)
  File "<string>", line 2, in raise_from
  File "/Users/miklash90/projects/lessons1/env/lib/python3.5/site-packages/telegram/vendor/ptb_urllib3/urllib3/connectionpool.py", line 398, in _make_request
    httplib_response = conn.getresponse()
  File "/Library/Frameworks/Python.framework/Versions/3.5/lib/python3.5/http/client.py", line 1198, in getresponse
    response.begin()
  File "/Library/Frameworks/Python.framework/Versions/3.5/lib/python3.5/http/client.py", line 297, in begin
    version, status, reason = self._read_status()
  File "/Library/Frameworks/Python.framework/Versions/3.5/lib/python3.5/http/client.py", line 258, in _read_status
    line = str(self.fp.readline(_MAXLINE + 1), "iso-8859-1")
  File "/Library/Frameworks/Python.framework/Versions/3.5/lib/python3.5/socket.py", line 576, in readinto
    return self._sock.recv_into(b)
  File "/Library/Frameworks/Python.framework/Versions/3.5/lib/python3.5/ssl.py", line 937, in recv_into
    return self.read(nbytes, buffer)
  File "/Library/Frameworks/Python.framework/Versions/3.5/lib/python3.5/ssl.py", line 799, in read
    return self._sslobj.read(len, buffer)
  File "/Library/Frameworks/Python.framework/Versions/3.5/lib/python3.5/ssl.py", line 583, in read
    v = self._sslobj.read(len, buffer)
socket.timeout: The read operation timed out

During handling of the above exception, another exception occurred:

Traceback (most recent call last):
  File "/Users/miklash90/projects/lessons1/env/lib/python3.5/site-packages/telegram/utils/request.py", line 190, in _request_wrapper
    resp = self._con_pool.request(*args, **kwargs)
  File "/Users/miklash90/projects/lessons1/env/lib/python3.5/site-packages/telegram/vendor/ptb_urllib3/urllib3/request.py", line 70, in request
    **urlopen_kw)
  File "/Users/miklash90/projects/lessons1/env/lib/python3.5/site-packages/telegram/vendor/ptb_urllib3/urllib3/request.py", line 148, in request_encode_body
    return self.urlopen(method, url, **extra_kw)
  File "/Users/miklash90/projects/lessons1/env/lib/python3.5/site-packages/telegram/vendor/ptb_urllib3/urllib3/poolmanager.py", line 244, in urlopen
    response = conn.urlopen(method, u.request_uri, **kw)
  File "/Users/miklash90/projects/lessons1/env/lib/python3.5/site-packages/telegram/vendor/ptb_urllib3/urllib3/connectionpool.py", line 666, in urlopen
    _stacktrace=sys.exc_info()[2])
  File "/Users/miklash90/projects/lessons1/env/lib/python3.5/site-packages/telegram/vendor/ptb_urllib3/urllib3/util/retry.py", line 347, in increment
    raise six.reraise(type(error), error, _stacktrace)
  File "/Users/miklash90/projects/lessons1/env/lib/python3.5/site-packages/telegram/vendor/ptb_urllib3/urllib3/packages/six.py", line 686, in reraise
    raise value
  File "/Users/miklash90/projects/lessons1/env/lib/python3.5/site-packages/telegram/vendor/ptb_urllib3/urllib3/connectionpool.py", line 617, in urlopen
    chunked=chunked)
  File "/Users/miklash90/projects/lessons1/env/lib/python3.5/site-packages/telegram/vendor/ptb_urllib3/urllib3/connectionpool.py", line 405, in _make_request
    exc_cls=ReadTimeoutError)
  File "/Users/miklash90/projects/lessons1/env/lib/python3.5/site-packages/telegram/vendor/ptb_urllib3/urllib3/connectionpool.py", line 321, in _raise_timeout
    raise exc_cls(*args)
telegram.vendor.ptb_urllib3.urllib3.exceptions.ReadTimeoutError: HTTPSConnectionPool(host='api.telegram.org', port=443): Read timed out. (read timeout=12.0)

During handling of the above exception, another exception occurred:

Traceback (most recent call last):
  File "/Users/miklash90/projects/lessons1/env/lib/python3.5/site-packages/telegram/ext/updater.py", line 286, in _start_polling
    allowed_updates=allowed_updates)
  File "/Users/miklash90/projects/lessons1/env/lib/python3.5/site-packages/telegram/bot.py", line 60, in decorator
    result = func(self, *args, **kwargs)
  File "/Users/miklash90/projects/lessons1/env/lib/python3.5/site-packages/telegram/bot.py", line 1720, in get_updates
    result = self._request.post(url, data, timeout=float(read_latency) + float(timeout))
  File "/Users/miklash90/projects/lessons1/env/lib/python3.5/site-packages/telegram/utils/request.py", line 272, in post
    **urlopen_kwargs)
  File "/Users/miklash90/projects/lessons1/env/lib/python3.5/site-packages/telegram/utils/request.py", line 192, in _request_wrapper
    raise TimedOut()
telegram.error.TimedOut: Timed out
telegram.ext.updater - ERROR - Error while getting Updates: Timed out
telegram.ext.dispatcher - ERROR - No error handlers are registered, logging exception...
Traceback (most recent call last):
  File "/Users/miklash90/projects/lessons1/env/lib/python3.5/site-packages/telegram/vendor/ptb_urllib3/urllib3/connectionpool.py", line 402, in _make_request
    six.raise_from(e, None)
  File "<string>", line 2, in raise_from
  File "/Users/miklash90/projects/lessons1/env/lib/python3.5/site-packages/telegram/vendor/ptb_urllib3/urllib3/connectionpool.py", line 398, in _make_request
    httplib_response = conn.getresponse()
  File "/Library/Frameworks/Python.framework/Versions/3.5/lib/python3.5/http/client.py", line 1198, in getresponse
    response.begin()
  File "/Library/Frameworks/Python.framework/Versions/3.5/lib/python3.5/http/client.py", line 297, in begin
    version, status, reason = self._read_status()
  File "/Library/Frameworks/Python.framework/Versions/3.5/lib/python3.5/http/client.py", line 258, in _read_status
    line = str(self.fp.readline(_MAXLINE + 1), "iso-8859-1")
  File "/Library/Frameworks/Python.framework/Versions/3.5/lib/python3.5/socket.py", line 576, in readinto
    return self._sock.recv_into(b)
  File "/Library/Frameworks/Python.framework/Versions/3.5/lib/python3.5/ssl.py", line 937, in recv_into
    return self.read(nbytes, buffer)
  File "/Library/Frameworks/Python.framework/Versions/3.5/lib/python3.5/ssl.py", line 799, in read
    return self._sslobj.read(len, buffer)
  File "/Library/Frameworks/Python.framework/Versions/3.5/lib/python3.5/ssl.py", line 583, in read
    v = self._sslobj.read(len, buffer)
socket.timeout: The read operation timed out

During handling of the above exception, another exception occurred:

Traceback (most recent call last):
  File "/Users/miklash90/projects/lessons1/env/lib/python3.5/site-packages/telegram/utils/request.py", line 190, in _request_wrapper
    resp = self._con_pool.request(*args, **kwargs)
  File "/Users/miklash90/projects/lessons1/env/lib/python3.5/site-packages/telegram/vendor/ptb_urllib3/urllib3/request.py", line 70, in request
    **urlopen_kw)
  File "/Users/miklash90/projects/lessons1/env/lib/python3.5/site-packages/telegram/vendor/ptb_urllib3/urllib3/request.py", line 148, in request_encode_body
    return self.urlopen(method, url, **extra_kw)
  File "/Users/miklash90/projects/lessons1/env/lib/python3.5/site-packages/telegram/vendor/ptb_urllib3/urllib3/poolmanager.py", line 244, in urlopen
    response = conn.urlopen(method, u.request_uri, **kw)
  File "/Users/miklash90/projects/lessons1/env/lib/python3.5/site-packages/telegram/vendor/ptb_urllib3/urllib3/connectionpool.py", line 666, in urlopen
    _stacktrace=sys.exc_info()[2])
  File "/Users/miklash90/projects/lessons1/env/lib/python3.5/site-packages/telegram/vendor/ptb_urllib3/urllib3/util/retry.py", line 347, in increment
    raise six.reraise(type(error), error, _stacktrace)
  File "/Users/miklash90/projects/lessons1/env/lib/python3.5/site-packages/telegram/vendor/ptb_urllib3/urllib3/packages/six.py", line 686, in reraise
    raise value
  File "/Users/miklash90/projects/lessons1/env/lib/python3.5/site-packages/telegram/vendor/ptb_urllib3/urllib3/connectionpool.py", line 617, in urlopen
    chunked=chunked)
  File "/Users/miklash90/projects/lessons1/env/lib/python3.5/site-packages/telegram/vendor/ptb_urllib3/urllib3/connectionpool.py", line 405, in _make_request
    exc_cls=ReadTimeoutError)
  File "/Users/miklash90/projects/lessons1/env/lib/python3.5/site-packages/telegram/vendor/ptb_urllib3/urllib3/connectionpool.py", line 321, in _raise_timeout
    raise exc_cls(*args)
telegram.vendor.ptb_urllib3.urllib3.exceptions.ReadTimeoutError: HTTPSConnectionPool(host='api.telegram.org', port=443): Read timed out. (read timeout=12.0)

During handling of the above exception, another exception occurred:

Traceback (most recent call last):
  File "/Users/miklash90/projects/lessons1/env/lib/python3.5/site-packages/telegram/ext/updater.py", line 286, in _start_polling
    allowed_updates=allowed_updates)
  File "/Users/miklash90/projects/lessons1/env/lib/python3.5/site-packages/telegram/bot.py", line 60, in decorator
    result = func(self, *args, **kwargs)
  File "/Users/miklash90/projects/lessons1/env/lib/python3.5/site-packages/telegram/bot.py", line 1720, in get_updates
    result = self._request.post(url, data, timeout=float(read_latency) + float(timeout))
  File "/Users/miklash90/projects/lessons1/env/lib/python3.5/site-packages/telegram/utils/request.py", line 272, in post
    **urlopen_kwargs)
  File "/Users/miklash90/projects/lessons1/env/lib/python3.5/site-packages/telegram/utils/request.py", line 192, in _request_wrapper
    raise TimedOut()
telegram.error.TimedOut: Timed out
telegram.ext.updater - ERROR - Error while getting Updates: Timed out
telegram.ext.dispatcher - ERROR - No error handlers are registered, logging exception...
Traceback (most recent call last):
  File "/Users/miklash90/projects/lessons1/env/lib/python3.5/site-packages/telegram/vendor/ptb_urllib3/urllib3/connectionpool.py", line 402, in _make_request
    six.raise_from(e, None)
  File "<string>", line 2, in raise_from
  File "/Users/miklash90/projects/lessons1/env/lib/python3.5/site-packages/telegram/vendor/ptb_urllib3/urllib3/connectionpool.py", line 398, in _make_request
    httplib_response = conn.getresponse()
  File "/Library/Frameworks/Python.framework/Versions/3.5/lib/python3.5/http/client.py", line 1198, in getresponse
    response.begin()
  File "/Library/Frameworks/Python.framework/Versions/3.5/lib/python3.5/http/client.py", line 297, in begin
    version, status, reason = self._read_status()
  File "/Library/Frameworks/Python.framework/Versions/3.5/lib/python3.5/http/client.py", line 258, in _read_status
    line = str(self.fp.readline(_MAXLINE + 1), "iso-8859-1")
  File "/Library/Frameworks/Python.framework/Versions/3.5/lib/python3.5/socket.py", line 576, in readinto
    return self._sock.recv_into(b)
  File "/Library/Frameworks/Python.framework/Versions/3.5/lib/python3.5/ssl.py", line 937, in recv_into
    return self.read(nbytes, buffer)
  File "/Library/Frameworks/Python.framework/Versions/3.5/lib/python3.5/ssl.py", line 799, in read
    return self._sslobj.read(len, buffer)
  File "/Library/Frameworks/Python.framework/Versions/3.5/lib/python3.5/ssl.py", line 583, in read
    v = self._sslobj.read(len, buffer)
socket.timeout: The read operation timed out

During handling of the above exception, another exception occurred:

Traceback (most recent call last):
  File "/Users/miklash90/projects/lessons1/env/lib/python3.5/site-packages/telegram/utils/request.py", line 190, in _request_wrapper
    resp = self._con_pool.request(*args, **kwargs)
  File "/Users/miklash90/projects/lessons1/env/lib/python3.5/site-packages/telegram/vendor/ptb_urllib3/urllib3/request.py", line 70, in request
    **urlopen_kw)
  File "/Users/miklash90/projects/lessons1/env/lib/python3.5/site-packages/telegram/vendor/ptb_urllib3/urllib3/request.py", line 148, in request_encode_body
    return self.urlopen(method, url, **extra_kw)
  File "/Users/miklash90/projects/lessons1/env/lib/python3.5/site-packages/telegram/vendor/ptb_urllib3/urllib3/poolmanager.py", line 244, in urlopen
    response = conn.urlopen(method, u.request_uri, **kw)
  File "/Users/miklash90/projects/lessons1/env/lib/python3.5/site-packages/telegram/vendor/ptb_urllib3/urllib3/connectionpool.py", line 666, in urlopen
    _stacktrace=sys.exc_info()[2])
  File "/Users/miklash90/projects/lessons1/env/lib/python3.5/site-packages/telegram/vendor/ptb_urllib3/urllib3/util/retry.py", line 347, in increment
    raise six.reraise(type(error), error, _stacktrace)
  File "/Users/miklash90/projects/lessons1/env/lib/python3.5/site-packages/telegram/vendor/ptb_urllib3/urllib3/packages/six.py", line 686, in reraise
    raise value
  File "/Users/miklash90/projects/lessons1/env/lib/python3.5/site-packages/telegram/vendor/ptb_urllib3/urllib3/connectionpool.py", line 617, in urlopen
    chunked=chunked)
  File "/Users/miklash90/projects/lessons1/env/lib/python3.5/site-packages/telegram/vendor/ptb_urllib3/urllib3/connectionpool.py", line 405, in _make_request
    exc_cls=ReadTimeoutError)
  File "/Users/miklash90/projects/lessons1/env/lib/python3.5/site-packages/telegram/vendor/ptb_urllib3/urllib3/connectionpool.py", line 321, in _raise_timeout
    raise exc_cls(*args)
telegram.vendor.ptb_urllib3.urllib3.exceptions.ReadTimeoutError: HTTPSConnectionPool(host='api.telegram.org', port=443): Read timed out. (read timeout=12.0)

During handling of the above exception, another exception occurred:

Traceback (most recent call last):
  File "/Users/miklash90/projects/lessons1/env/lib/python3.5/site-packages/telegram/ext/updater.py", line 286, in _start_polling
    allowed_updates=allowed_updates)
  File "/Users/miklash90/projects/lessons1/env/lib/python3.5/site-packages/telegram/bot.py", line 60, in decorator
    result = func(self, *args, **kwargs)
  File "/Users/miklash90/projects/lessons1/env/lib/python3.5/site-packages/telegram/bot.py", line 1720, in get_updates
    result = self._request.post(url, data, timeout=float(read_latency) + float(timeout))
  File "/Users/miklash90/projects/lessons1/env/lib/python3.5/site-packages/telegram/utils/request.py", line 272, in post
    **urlopen_kwargs)
  File "/Users/miklash90/projects/lessons1/env/lib/python3.5/site-packages/telegram/utils/request.py", line 192, in _request_wrapper
    raise TimedOut()
telegram.error.TimedOut: Timed out
telegram.ext.updater - ERROR - Error while getting Updates: Conflict: terminated by other getUpdates request; make sure that only one bot instance is running (409)
telegram.ext.dispatcher - ERROR - No error handlers are registered, logging exception...
Traceback (most recent call last):
  File "/Users/miklash90/projects/lessons1/env/lib/python3.5/site-packages/telegram/ext/updater.py", line 286, in _start_polling
    allowed_updates=allowed_updates)
  File "/Users/miklash90/projects/lessons1/env/lib/python3.5/site-packages/telegram/bot.py", line 60, in decorator
    result = func(self, *args, **kwargs)
  File "/Users/miklash90/projects/lessons1/env/lib/python3.5/site-packages/telegram/bot.py", line 1720, in get_updates
    result = self._request.post(url, data, timeout=float(read_latency) + float(timeout))
  File "/Users/miklash90/projects/lessons1/env/lib/python3.5/site-packages/telegram/utils/request.py", line 272, in post
    **urlopen_kwargs)
  File "/Users/miklash90/projects/lessons1/env/lib/python3.5/site-packages/telegram/utils/request.py", line 220, in _request_wrapper
    raise NetworkError('{0} ({1})'.format(message, resp.status))
telegram.error.NetworkError: Conflict: terminated by other getUpdates request; make sure that only one bot instance is running (409)
telegram.ext.updater - ERROR - Error while getting Updates: Conflict: terminated by other getUpdates request; make sure that only one bot instance is running (409)
telegram.ext.dispatcher - ERROR - No error handlers are registered, logging exception...
Traceback (most recent call last):
  File "/Users/miklash90/projects/lessons1/env/lib/python3.5/site-packages/telegram/ext/updater.py", line 286, in _start_polling
    allowed_updates=allowed_updates)
  File "/Users/miklash90/projects/lessons1/env/lib/python3.5/site-packages/telegram/bot.py", line 60, in decorator
    result = func(self, *args, **kwargs)
  File "/Users/miklash90/projects/lessons1/env/lib/python3.5/site-packages/telegram/bot.py", line 1720, in get_updates
    result = self._request.post(url, data, timeout=float(read_latency) + float(timeout))
  File "/Users/miklash90/projects/lessons1/env/lib/python3.5/site-packages/telegram/utils/request.py", line 272, in post
    **urlopen_kwargs)
  File "/Users/miklash90/projects/lessons1/env/lib/python3.5/site-packages/telegram/utils/request.py", line 220, in _request_wrapper
    raise NetworkError('{0} ({1})'.format(message, resp.status))
telegram.error.NetworkError: Conflict: terminated by other getUpdates request; make sure that only one bot instance is running (409)
telegram.ext.updater - ERROR - Error while getting Updates: Conflict: terminated by other getUpdates request; make sure that only one bot instance is running (409)
telegram.ext.dispatcher - ERROR - No error handlers are registered, logging exception...
Traceback (most recent call last):
  File "/Users/miklash90/projects/lessons1/env/lib/python3.5/site-packages/telegram/ext/updater.py", line 286, in _start_polling
    allowed_updates=allowed_updates)
  File "/Users/miklash90/projects/lessons1/env/lib/python3.5/site-packages/telegram/bot.py", line 60, in decorator
    result = func(self, *args, **kwargs)
  File "/Users/miklash90/projects/lessons1/env/lib/python3.5/site-packages/telegram/bot.py", line 1720, in get_updates
    result = self._request.post(url, data, timeout=float(read_latency) + float(timeout))
  File "/Users/miklash90/projects/lessons1/env/lib/python3.5/site-packages/telegram/utils/request.py", line 272, in post
    **urlopen_kwargs)
  File "/Users/miklash90/projects/lessons1/env/lib/python3.5/site-packages/telegram/utils/request.py", line 220, in _request_wrapper
    raise NetworkError('{0} ({1})'.format(message, resp.status))
telegram.error.NetworkError: Conflict: terminated by other getUpdates request; make sure that only one bot instance is running (409)
telegram.ext.updater - ERROR - Error while getting Updates: Conflict: terminated by other getUpdates request; make sure that only one bot instance is running (409)
telegram.ext.dispatcher - ERROR - No error handlers are registered, logging exception...
Traceback (most recent call last):
  File "/Users/miklash90/projects/lessons1/env/lib/python3.5/site-packages/telegram/ext/updater.py", line 286, in _start_polling
    allowed_updates=allowed_updates)
  File "/Users/miklash90/projects/lessons1/env/lib/python3.5/site-packages/telegram/bot.py", line 60, in decorator
    result = func(self, *args, **kwargs)
  File "/Users/miklash90/projects/lessons1/env/lib/python3.5/site-packages/telegram/bot.py", line 1720, in get_updates
    result = self._request.post(url, data, timeout=float(read_latency) + float(timeout))
  File "/Users/miklash90/projects/lessons1/env/lib/python3.5/site-packages/telegram/utils/request.py", line 272, in post
    **urlopen_kwargs)
  File "/Users/miklash90/projects/lessons1/env/lib/python3.5/site-packages/telegram/utils/request.py", line 220, in _request_wrapper
    raise NetworkError('{0} ({1})'.format(message, resp.status))
telegram.error.NetworkError: Conflict: terminated by other getUpdates request; make sure that only one bot instance is running (409)
telegram.ext.updater - ERROR - Error while getting Updates: Conflict: terminated by other getUpdates request; make sure that only one bot instance is running (409)
telegram.ext.dispatcher - ERROR - No error handlers are registered, logging exception...
Traceback (most recent call last):
  File "/Users/miklash90/projects/lessons1/env/lib/python3.5/site-packages/telegram/ext/updater.py", line 286, in _start_polling
    allowed_updates=allowed_updates)
  File "/Users/miklash90/projects/lessons1/env/lib/python3.5/site-packages/telegram/bot.py", line 60, in decorator
    result = func(self, *args, **kwargs)
  File "/Users/miklash90/projects/lessons1/env/lib/python3.5/site-packages/telegram/bot.py", line 1720, in get_updates
    result = self._request.post(url, data, timeout=float(read_latency) + float(timeout))
  File "/Users/miklash90/projects/lessons1/env/lib/python3.5/site-packages/telegram/utils/request.py", line 272, in post
    **urlopen_kwargs)
  File "/Users/miklash90/projects/lessons1/env/lib/python3.5/site-packages/telegram/utils/request.py", line 220, in _request_wrapper
    raise NetworkError('{0} ({1})'.format(message, resp.status))
telegram.error.NetworkError: Conflict: terminated by other getUpdates request; make sure that only one bot instance is running (409)
telegram.ext.updater - ERROR - Error while getting Updates: Conflict: terminated by other getUpdates request; make sure that only one bot instance is running (409)
telegram.ext.dispatcher - ERROR - No error handlers are registered, logging exception...
Traceback (most recent call last):
  File "/Users/miklash90/projects/lessons1/env/lib/python3.5/site-packages/telegram/ext/updater.py", line 286, in _start_polling
    allowed_updates=allowed_updates)
  File "/Users/miklash90/projects/lessons1/env/lib/python3.5/site-packages/telegram/bot.py", line 60, in decorator
    result = func(self, *args, **kwargs)
  File "/Users/miklash90/projects/lessons1/env/lib/python3.5/site-packages/telegram/bot.py", line 1720, in get_updates
    result = self._request.post(url, data, timeout=float(read_latency) + float(timeout))
  File "/Users/miklash90/projects/lessons1/env/lib/python3.5/site-packages/telegram/utils/request.py", line 272, in post
    **urlopen_kwargs)
  File "/Users/miklash90/projects/lessons1/env/lib/python3.5/site-packages/telegram/utils/request.py", line 220, in _request_wrapper
    raise NetworkError('{0} ({1})'.format(message, resp.status))
telegram.error.NetworkError: Conflict: terminated by other getUpdates request; make sure that only one bot instance is running (409)
telegram.ext.updater - ERROR - Error while getting Updates: Conflict: terminated by other getUpdates request; make sure that only one bot instance is running (409)
telegram.ext.dispatcher - ERROR - No error handlers are registered, logging exception...
Traceback (most recent call last):
  File "/Users/miklash90/projects/lessons1/env/lib/python3.5/site-packages/telegram/ext/updater.py", line 286, in _start_polling
    allowed_updates=allowed_updates)
  File "/Users/miklash90/projects/lessons1/env/lib/python3.5/site-packages/telegram/bot.py", line 60, in decorator
    result = func(self, *args, **kwargs)
  File "/Users/miklash90/projects/lessons1/env/lib/python3.5/site-packages/telegram/bot.py", line 1720, in get_updates
    result = self._request.post(url, data, timeout=float(read_latency) + float(timeout))
  File "/Users/miklash90/projects/lessons1/env/lib/python3.5/site-packages/telegram/utils/request.py", line 272, in post
    **urlopen_kwargs)
  File "/Users/miklash90/projects/lessons1/env/lib/python3.5/site-packages/telegram/utils/request.py", line 220, in _request_wrapper
    raise NetworkError('{0} ({1})'.format(message, resp.status))
telegram.error.NetworkError: Conflict: terminated by other getUpdates request; make sure that only one bot instance is running (409)
telegram.ext.updater - ERROR - Error while getting Updates: Conflict: terminated by other getUpdates request; make sure that only one bot instance is running (409)
telegram.ext.dispatcher - ERROR - No error handlers are registered, logging exception...
Traceback (most recent call last):
  File "/Users/miklash90/projects/lessons1/env/lib/python3.5/site-packages/telegram/ext/updater.py", line 286, in _start_polling
    allowed_updates=allowed_updates)
  File "/Users/miklash90/projects/lessons1/env/lib/python3.5/site-packages/telegram/bot.py", line 60, in decorator
    result = func(self, *args, **kwargs)
  File "/Users/miklash90/projects/lessons1/env/lib/python3.5/site-packages/telegram/bot.py", line 1720, in get_updates
    result = self._request.post(url, data, timeout=float(read_latency) + float(timeout))
  File "/Users/miklash90/projects/lessons1/env/lib/python3.5/site-packages/telegram/utils/request.py", line 272, in post
    **urlopen_kwargs)
  File "/Users/miklash90/projects/lessons1/env/lib/python3.5/site-packages/telegram/utils/request.py", line 220, in _request_wrapper
    raise NetworkError('{0} ({1})'.format(message, resp.status))
telegram.error.NetworkError: Conflict: terminated by other getUpdates request; make sure that only one bot instance is running (409)
telegram.ext.updater - WARNING - Exiting immediately!
